Workbook

Sheet JSWENERGY stock Analysis
A1: Date | B1: Column1 | C1: Day | D1: Month | E1: Quarter | F1: Year | G1: series | H1: OPEN | I1: HIGH | J1: LOW | K1: PREV. CLOSE | L1: ltp | M1: close | N1: vwap | O1: 52W H | P1: 52W L | Q1: VOLUME | R1: No of trades
A2: 45729 | B2: =TEXT(A2,"mmm"&"yyy") -> Mar2025 | C2: Thursday | D2: March | E2: Q1 | F2: 2025 | G2: EQ | H2: 519.65 | I2: 523.65 | J2: 508.1 | K2: 515.2 | L2: 513.55 | M2: 514.1 | N2: 516.04 | O2: 804.9 | P2: 418.75 | Q2: 4303396 | R2: 69870
A3: 45728 | B3: =TEXT(A3,"mmm"&"yyy") -> Mar2025 | C3: Wednesday | D3: March | E3: Q1 | F3: 2025 | G3: EQ | H3: 517 | I3: 523.85 | J3: 506.3 | K3: 513.75 | L3: 518 | M3: 515.2 | N3: 515.17 | O3: 804.9 | P3: 418.75 | Q3: 4974269 | R3: 67643
A4: 45727 | B4: =TEXT(A4,"mmm"&"yyy") -> Mar2025 | C4: Tuesday | D4: March | E4: Q1 | F4: 2025 | G4: EQ | H4: 501 | I4: 519.5 | J4: 498.1 | K4: 505.35 | L4: 516.25 | M4: 513.75 | N4: 512.6 | O4: 804.9 | P4: 418.75 | Q4: 6225817 | R4: 91766
A5: 45726 | B5: =TEXT(A5,"mmm"&"yyy") -> Mar2025 | C5: Monday | D5: March | E5: Q1 | F5: 2025 | G5: EQ | H5: 491 | I5: 514.4 | J5: 490.25 | K5: 491.7 | L5: 505.3 | M5: 505.35 | N5: 507.56 | O5: 804.9 | P5: 418.75 | Q5: 9854493 | R5: 117087
A6: 45723 | B6: =TEXT(A6,"mmm"&"yyy") -> Mar2025 | C6: Friday | D6: March | E6: Q1 | F6: 2025 | G6: EQ | H6: 498.05 | I6: 506.35 | J6: 486.25 | K6: 499.6 | L6: 491.25 | M6: 491.7 | N6: 495.71 | O6: 804.9 | P6: 418.75 | Q6: 4329758 | R6: 66495
A7: 45722 | B7: =TEXT(A7,"mmm"&"yyy") -> Mar2025 | C7: Thursday | D7: March | E7: Q1 | F7: 2025 | G7: EQ | H7: 509.5 | I7: 517 | J7: 494.6 | K7: 509.1 | L7: 498.4 | M7: 499.6 | N7: 502.29 | O7: 804.9 | P7: 418.75 | Q7: 4847592 | R7: 80445
A8: 45721 | B8: =TEXT(A8,"mmm"&"yyy") -> Mar2025 | C8: Wednesday | D8: March | E8: Q1 | F8: 2025 | G8: EQ | H8: 479.25 | I8: 514.7 | J8: 479.25 | K8: 481.25 | L8: 508.95 | M8: 509.1 | N8: 501.46 | O8: 804.9 | P8: 418.75 | Q8: 7368531 | R8: 91435
A9: 45720 | B9: =TEXT(A9,"mmm"&"yyy") -> Mar2025 | C9: Tuesday | D9: March | E9: Q1 | F9: 2025 | G9: EQ | H9: 471.5 | I9: 485.35 | J9: 466.55 | K9: 473.85 | L9: 481.4 | M9: 481.25 | N9: 476.96 | O9: 804.9 | P9: 418.75 | Q9: 4501589 | R9: 74512
A10: 45719 | B10: =TEXT(A10,"mmm"&"yyy") -> Mar2025 | C10: Monday | D10: March | E10: Q1 | F10: 2025 | G10: EQ | H10: 464.7 | I10: 477.25 | J10: 449.25 | K10: 464.1 | L10: 474.3 | M10: 473.85 | N10: 464.36 | O10: 804.9 | P10: 418.75 | Q10: 5530160 | R10: 85352
A11: 45716 | B11: =TEXT(A11,"mmm"&"yyy") -> Feb2025 | C11: Friday | D11: February | E11: Q1 | F11: 2025 | G11: EQ | H11: 453.05 | I11: 468 | J11: 442.35 | K11: 458.8 | L11: 462.7 | M11: 464.1 | N11: 455.55 | O11: 804.9 | P11: 418.75 | Q11: 6930904 | R11: 83261
A12: 45715 | B12: =TEXT(A12,"mmm"&"yyy") -> Feb2025 | C12: Thursday | D12: February | E12: Q1 | F12: 2025 | G12: EQ | H12: 474.5 | I12: 476.25 | J12: 454.25 | K12: 467.25 | L12: 458.55 | M12: 458.8 | N12: 464.19 | O12: 804.9 | P12: 418.75 | Q12: 3135406 | R12: 51352
A13: 45713 | B13: =TEXT(A13,"mmm"&"yyy") -> Feb2025 | C13: Tuesday | D13: February | E13: Q1 | F13: 2025 | G13: EQ | H13: 482 | I13: 482.8 | J13: 466.2 | K13: 479.7 | L13: 467 | M13: 467.25 | N13: 472.53 | O13: 804.9 | P13: 418.75 | Q13: 3336761 | R13: 62013
... A248: 45369 | B248: =TEXT(A248,"mmm"&"yyy") -> Mar2024 | C248: Monday | D248: March | E248: Q1 | F248: 2024 | G248: EQ | H248: 500 | I248: 502.15 | J248: 481 | K248: 497.9 | L248: 494.3 | M248: 495.4 | N248: 491.63 | O248: 537.95 | P248: 221 | Q248: 2663154 | R248: 54144

Sheet Trend Analysis of Stock
A1: Date | B1: close | E1: Trend Analysis
A2: 45729 | B2: 514.1 | E2: Month | F2: Closing Stock
A3: 45728 | B3: 515.2 | E3: 45352 | F3: 505.7625
A4: 45727 | B4: 513.75 | E4: 45383 | F4: 601.5325
A5: 45726 | B5: 505.35 | E5: 45413 | F5: 599.55227
A6: 45723 | B6: 491.7 | E6: 45444 | F6: 674.62895
A7: 45722 | B7: 499.6 | E7: 45474 | F7: 714.73864
A8: 45721 | B8: 509.1 | E8: 45505 | F8: 700.57143
A9: 45720 | B9: 481.25 | E9: 45536 | F9: 746.53333
A10: 45719 | B10: 473.85 | E10: 45566 | F10: 690.64318
A11: 45716 | B11: 464.1 | E11: 45597 | F11: 694.43421
A12: 45715 | B12: 458.8 | E12: 45627 | F12: 663.20476
A13: 45713 | B13: 467.25 | E13: 45658 | F13: 558.59348
A14: 45712 | B14: 479.7 | E14: 45689 | F14: 466.895
A15: 45709 | B15: 496.6 | E15: 45717 | F15: 500.43333
A16: 45708 | B16: 468.55 | E16: 45748 | F16: =TREND($F$3:$F$15,$E$3:$E$15,E16:E20) -> 588.12003
A17: 45707 | B17: 454.85 | E17: 45778 | F17: =TREND($F$3:$F$15,$E$3:$E$15,E17:E21) -> 582.99556
A18: 45706 | B18: 440.4 | E18: 45809 | F18: =TREND($F$3:$F$15,$E$3:$E$15,E18:E22) -> 577.70028
A19: 45705 | B19: 431.5 | E19: 45839 | F19: =TREND($F$3:$F$15,$E$3:$E$15,E19:E23) -> 572.57581
A20: 45702 | B20: 437.1 | E20: 45870 | F20: =TREND($F$3:$F$15,$E$3:$E$15,E20:E24) -> 567.28053
A21: 45701 | B21: 467.65
A22: 45700 | B22: 467.6
A23: 45699 | B23: 466.9
A24: 45698 | B24: 476.9
A25: 45695 | B25: 484.65
A26: 45694 | B26: 494.2
A27: 45693 | B27: 493.8
A28: 45692 | B28: 469.7
A29: 45691 | B29: 445.65
A30: 45689 | B30: 472
A31: 45688 | B31: 508.6
A32: 45687 | B32: 483.85
... A248: 45369 | B248: 495.4

Sheet Trend Analysis of Volume
A1: Date | B1: VOLUME | E1: Trend Analysis
A2: 45729 | B2: 4303396 | E2: Month | F2: Volume
A3: 45728 | B3: 4974269 | E3: 45352 | F3: 2637304.4
A4: 45727 | B4: 6225817 | E4: 45383 | F4: 4788333.2
A5: 45726 | B5: 9854493 | E5: 45413 | F5: 7082898.3
A6: 45723 | B6: 4329758 | E6: 45444 | F6: 4269067.4
A7: 45722 | B7: 4847592 | E7: 45474 | F7: 2643279.2
A8: 45721 | B8: 7368531 | E8: 45505 | F8: 2215317.8
A9: 45720 | B9: 4501589 | E9: 45536 | F9: 3262889.7
A10: 45719 | B10: 5530160 | E10: 45566 | F10: 2139249.1
A11: 45716 | B11: 6930904 | E11: 45597 | F11: 3120537.8
A12: 45715 | B12: 3135406 | E12: 45627 | F12: 3191871.7
A13: 45713 | B13: 3336761 | E13: 45658 | F13: 4659195.1
A14: 45712 | B14: 4578924 | E14: 45689 | F14: 6541046.7
A15: 45709 | B15: 25750317 | E15: 45717 | F15: 5770622.8
A16: 45708 | B16: 7733476 | E16: 45748 | F16: =TREND($F$3:$F$15,$E$3:$E$15,E16:E20) -> 4616762.1
A17: 45707 | B17: 4076153 | E17: 45778 | F17: =TREND($F$3:$F$15,$E$3:$E$15,E17:E21) -> 4700326.6
A18: 45706 | B18: 4154074 | E18: 45809 | F18: =TREND($F$3:$F$15,$E$3:$E$15,E18:E22) -> 4786676.6
A19: 45705 | B19: 6897917 | E19: 45839 | F19: =TREND($F$3:$F$15,$E$3:$E$15,E19:E23) -> 4870241.2
A20: 45702 | B20: 3885358 | E20: 45870 | F20: =TREND($F$3:$F$15,$E$3:$E$15,E20:E24) -> 4956591.2
A21: 45701 | B21: 1560258
A22: 45700 | B22: 2782225
A23: 45699 | B23: 3213487
A24: 45698 | B24: 6658769
A25: 45695 | B25: 2431783
A26: 45694 | B26: 3540027
A27: 45693 | B27: 14443076
A28: 45692 | B28: 7217597
A29: 45691 | B29: 12724924
A30: 45689 | B30: 5769497
A31: 45688 | B31: 3358679
A32: 45687 | B32: 9565616
... A248: 45369 | B248: 2663154

Sheet ROI Calculation
A1: Date | B1: OPEN | C1: close | D1: ROI for Stock | H1: ROI Month Wise
A2: 45729 | B2: 519.65 | C2: 514.1 | D2: =((C2-B2)+2)/B2*100 -> -0.68315212 | H2: Month | I2: ROI per month
A3: 45728 | B3: 517 | C3: 515.2 | D3: =((C3-B3)+2)/B3*100 -> 0.03868472 | H3: 45352 | I3: 0.84343676
A4: 45727 | B4: 501 | C4: 513.75 | D4: =((C4-B4)+2)/B4*100 -> 2.9441118 | H4: 45383 | I4: 1.0388981
A5: 45726 | B5: 491 | C5: 505.35 | D5: =((C5-B5)+2)/B5*100 -> 3.3299389 | H5: 45413 | I5: -0.30752783
A6: 45723 | B6: 498.05 | C6: 491.7 | D6: =((C6-B6)+2)/B6*100 -> -0.87340628 | H6: 45444 | I6: 0.34795602
A7: 45722 | B7: 509.5 | C7: 499.6 | D7: =((C7-B7)+2)/B7*100 -> -1.5505397 | H7: 45474 | I7: -0.20750462
A8: 45721 | B8: 479.25 | C8: 509.1 | D8: =((C8-B8)+2)/B8*100 -> 6.6458007 | H8: 45505 | I8: -0.20190307
A9: 45720 | B9: 471.5 | C9: 481.25 | D9: =((C9-B9)+2)/B9*100 -> 2.4920467 | H9: 45536 | I9: 0.2665124
A10: 45719 | B10: 464.7 | C10: 473.85 | D10: =((C10-B10)+2)/B10*100 -> 2.3993975 | H10: 45566 | I10: -0.23927007
A11: 45716 | B11: 453.05 | C11: 464.1 | D11: =((C11-B11)+2)/B11*100 -> 2.8804768 | H11: 45597 | I11: -0.31721794
A12: 45715 | B12: 474.5 | C12: 458.8 | D12: =((C12-B12)+2)/B12*100 -> -2.8872497 | H12: 45627 | I12: -0.20623238
A13: 45713 | B13: 482 | C13: 467.25 | D13: =((C13-B13)+2)/B13*100 -> -2.6452282 | H13: 45658 | I13: -0.39223721
A14: 45712 | B14: 494 | C14: 479.7 | D14: =((C14-B14)+2)/B14*100 -> -2.4898785 | H14: 45689 | I14: -0.099880417
A15: 45709 | B15: 474 | C15: 496.6 | D15: =((C15-B15)+2)/B15*100 -> 5.1898734 | H15: 45717 | I15: 1.638098
A16: 45708 | B16: 450 | C16: 468.55 | D16: =((C16-B16)+2)/B16*100 -> 4.5666667 | H16: 45748 | I16: =TREND($I$3:$I$15,$H$3:$H$15,H16:H21) -> 0.041119275
A17: 45707 | B17: 439 | C17: 454.85 | D17: =((C17-B17)+2)/B17*100 -> 4.0660592 | H17: 45778 | I17: =TREND($I$3:$I$15,$H$3:$H$15,H17:H22) -> 0.023436569
A18: 45706 | B18: 430.5 | C18: 440.4 | D18: =((C18-B18)+2)/B18*100 -> 2.7642276 | H18: 45809 | I18: =TREND($I$3:$I$15,$H$3:$H$15,H18:H23) -> 0.0051644405
A19: 45705 | B19: 436.05 | C19: 431.5 | D19: =((C19-B19)+2)/B19*100 -> -0.58479532 | H19: 45839 | I19: =TREND($I$3:$I$15,$H$3:$H$15,H19:H24) -> -0.012518265
A20: 45702 | B20: 469 | C20: 437.1 | D20: =((C20-B20)+2)/B20*100 -> -6.3752665 | H20: 45870 | I20: =TREND($I$3:$I$15,$H$3:$H$15,H20:H25) -> -0.030790394
A21: 45701 | B21: 468 | C21: 467.65 | D21: =((C21-B21)+2)/B21*100 -> 0.3525641 | H21: 45901 | I21: =TREND($I$3:$I$15,$H$3:$H$15,H21:H26) -> -0.049062522
A22: 45700 | B22: 466.85 | C22: 467.6 | D22: =((C22-B22)+2)/B22*100 -> 0.5890543
A23: 45699 | B23: 475.1 | C23: 466.9 | D23: =((C23-B23)+2)/B23*100 -> -1.3049884
A24: 45698 | B24: 483.6 | C24: 476.9 | D24: =((C24-B24)+2)/B24*100 -> -0.97187758
A25: 45695 | B25: 492.75 | C25: 484.65 | D25: =((C25-B25)+2)/B25*100 -> -1.2379503 | H25: Average ROI per Stock in 1 year period= | K25: =AVERAGE(I3:I15) -> 0.16639444
A26: 45694 | B26: 494 | C26: 494.2 | D26: =((C26-B26)+2)/B26*100 -> 0.44534413
A27: 45693 | B27: 474.85 | C27: 493.8 | D27: =((C27-B27)+2)/B27*100 -> 4.4119196 | H27: Forcasting on ROI for next 6 months= | K27: =AVERAGE(I16:I21) -> -0.0037751494
A28: 45692 | B28: 453.95 | C28: 469.7 | D28: =((C28-B28)+2)/B28*100 -> 3.9101223
A29: 45691 | B29: 474.8 | C29: 445.65 | D29: =((C29-B29)+2)/B29*100 -> -5.7181971
A30: 45689 | B30: 509.45 | C30: 472 | D30: =((C30-B30)+2)/B30*100 -> -6.9584846
A31: 45688 | B31: 489.5 | C31: 508.6 | D31: =((C31-B31)+2)/B31*100 -> 4.3105209
A32: 45687 | B32: 476.8 | C32: 483.85 | D32: =((C32-B32)+2)/B32*100 -> 1.8980705
A33: 45686 | B33: 463.7 | C33: 474.75 | D33: =((C33-B33)+2)/B33*100 -> 2.8143196
A34: 45685 | B34: 531.5 | C34: 504 | D34: =((C34-B34)+2)/B34*100 -> -4.7977422
A35: 45684 | B35: 540 | C35: 534.35 | D35: =((C35-B35)+2)/B35*100 -> -0.67592593
A36: 45681 | B36: 555 | C36: 544.15 | D36: =((C36-B36)+2)/B36*100 -> -1.5945946
A37: 45680 | B37: 546.95 | C37: 552.1 | D37: =((C37-B37)+2)/B37*100 -> 1.3072493
A38: 45679 | B38: 557.55 | C38: 550 | D38: =((C38-B38)+2)/B38*100 -> -0.99542642
A39: 45678 | B39: 581.9 | C39: 557.55 | D39: =((C39-B39)+2)/B39*100 -> -3.8408661
... A248: 45369 | B248: 500 | C248: 495.4 | D248: =((C248-B248)+2)/B248*100 -> -0.52

Sheet Standard D & Variance
A1: Date | B1: close | D1: ADJ closing price | G1: Return of the day
A2: 45729 | B2: 514.1 | D2: =B2-2 -> 512.1
A3: 45728 | B3: 515.2 | D3: =B3-2 -> 513.2 | G3: =(D3/D2)-1 -> 0.002148018
A4: 45727 | B4: 513.75 | D4: =B4-2 -> 511.75 | G4: =(D4/D3)-1 -> -0.0028254092 | I4: Average Return Per day | J4: =AVERAGE(G3:G248) -> 0.00027903943
A5: 45726 | B5: 505.35 | D5: =B5-2 -> 503.35 | G5: =(D5/D4)-1 -> -0.016414265 | I5: Standard Daviation for daily return | J5: =_xlfn.STDEV.P(G3:G248) -> 0.029540377
A6: 45723 | B6: 491.7 | D6: =B6-2 -> 489.7 | G6: =(D6/D5)-1 -> -0.027118307 | I6: Variance | J6: =_xlfn.VAR.P(G3:G248) -> 0.0008726339
A7: 45722 | B7: 499.6 | D7: =B7-2 -> 497.6 | G7: =(D7/D6)-1 -> 0.016132326
A8: 45721 | B8: 509.1 | D8: =B8-2 -> 507.1 | G8: =(D8/D7)-1 -> 0.01909164
A9: 45720 | B9: 481.25 | D9: =B9-2 -> 479.25 | G9: =(D9/D8)-1 -> -0.054920134
A10: 45719 | B10: 473.85 | D10: =B10-2 -> 471.85 | G10: =(D10/D9)-1 -> -0.015440793
A11: 45716 | B11: 464.1 | D11: =B11-2 -> 462.1 | G11: =(D11/D10)-1 -> -0.020663346
A12: 45715 | B12: 458.8 | D12: =B12-2 -> 456.8 | G12: =(D12/D11)-1 -> -0.011469379
A13: 45713 | B13: 467.25 | D13: =B13-2 -> 465.25 | G13: =(D13/D12)-1 -> 0.018498249
A14: 45712 | B14: 479.7 | D14: =B14-2 -> 477.7 | G14: =(D14/D13)-1 -> 0.026759807
A15: 45709 | B15: 496.6 | D15: =B15-2 -> 494.6 | G15: =(D15/D14)-1 -> 0.035377852
A16: 45708 | B16: 468.55 | D16: =B16-2 -> 466.55 | G16: =(D16/D15)-1 -> -0.056712495
A17: 45707 | B17: 454.85 | D17: =B17-2 -> 452.85 | G17: =(D17/D16)-1 -> -0.029364484
A18: 45706 | B18: 440.4 | D18: =B18-2 -> 438.4 | G18: =(D18/D17)-1 -> -0.031909021
... A248: 45369 | B248: 495.4 | D248: =B248-2 -> 493.4 | G248: =(D248/D247)-1 -> 0.026206323

Sheet Moving Averages calculation
A1: Date | B1: close | C1: Exponential Moving Average(EMA) 10 Days
A2: 45729 | B2: 514.1 | C2: =((B2-C3)*$O$5)+C3 -> 598.92785
A3: 45728 | B3: 515.2 | C3: =((B3-C4)*$O$5)+C4 -> 599.61751
A4: 45727 | B4: 513.75 | C4: =((B4-C5)*$O$5)+C5 -> 600.30383 | N4: Time Period | O4: 247
A5: 45726 | B5: 505.35 | C5: =((B5-C6)*$O$5)+C6 -> 601.00752 | N5: Multiplier | O5: =2/(COUNT(B2:B248)+1) -> 0.0080645161
A6: 45723 | B6: 491.7 | C6: =((B6-C7)*$O$5)+C7 -> 601.78522 | I6: ((CLOSE-PREV EMA)*MULTIPLIER)+PREV EMA | N6: Simple Moving Average(SMA) | O6: =SUM(B2:B248)/247 -> 636.45121
A7: 45722 | B7: 499.6 | C7: =((B7-C8)*$O$5)+C8 -> 602.68023 | N7: Exponential Moving Average(EMA) | O7: =AVERAGE(C2:C239) -> 595.59779
A8: 45721 | B8: 509.1 | C8: =((B8-C9)*$O$5)+C9 -> 603.51828
A9: 45720 | B9: 481.25 | C9: =((B9-C10)*$O$5)+C10 -> 604.2859
A10: 45719 | B10: 473.85 | C10: =((B10-C11)*$O$5)+C11 -> 605.2862
A11: 45716 | B11: 464.1 | C11: =((B11-C12)*$O$5)+C12 -> 606.35478
A12: 45715 | B12: 458.8 | C12: =((B12-C13)*$O$5)+C13 -> 607.51133
A13: 45713 | B13: 467.25 | C13: =((B13-C14)*$O$5)+C14 -> 608.72036
A14: 45712 | B14: 479.7 | C14: =((B14-C15)*$O$5)+C15 -> 609.87053
A15: 45709 | B15: 496.6 | C15: =((B15-C16)*$O$5)+C16 -> 610.92882
A16: 45708 | B16: 468.55 | C16: =((B16-C17)*$O$5)+C17 -> 611.85833
A17: 45707 | B17: 454.85 | C17: =((B17-C18)*$O$5)+C18 -> 613.02343
A18: 45706 | B18: 440.4 | C18: =((B18-C19)*$O$5)+C19 -> 614.3094
A19: 45705 | B19: 431.5 | C19: =((B19-C20)*$O$5)+C20 -> 615.7233
... A238: 45385 | B238: 581.35 | C238: =((B238-C239)*$O$5)+C239 -> 511.24496
A239: 45384 | B239: 542.2 | C239: =AVERAGE(B239:B248) -> 510.675 | D239: EMA
A240: 45383 | B240: 518.45
A241: 45379 | B241: 528.9
A242: 45378 | B242: 516.65
A243: 45377 | B243: 513.2
A244: 45373 | B244: 515.45
A245: 45372 | B245: 504.55
A246: 45371 | B246: 489.15
A247: 45370 | B247: 482.8
A248: 45369 | B248: 495.4

Sheet RSI Calculation
A1: Date | B1: close | C1: change | D1: Gain | E1: Loss | F1: AVG Gain | G1: AVG Loss | H1: RS | I1: RSI
A2: 45729 | B2: 514.1 | C2: =B2-B3 -> -1.1 | D2: =IF(C2>0,C2,0) -> 0 | E2: =IF(C2>0,0,ABS(C2)) -> 1.1 | F2: =AVERAGE(D2:D15) -> 7.275 | G2: =AVERAGE(E2:E15) -> 4.0214286 | H2: =F2/G2 -> 1.8090586 | I2: =IF(G2=0,100,100-(100/(1+H2))) -> 64.400885
A3: 45728 | B3: 515.2 | C3: =B3-B4 -> 1.45 | D3: =IF(C3>0,C3,0) -> 1.45 | E3: =IF(C3>0,0,ABS(C3)) -> 0 | F3: =AVERAGE(D3:D16) -> 8.2535714 | G3: =AVERAGE(E3:E16) -> 3.9428571 | H3: =F3/G3 -> 2.0932971 | I3: =IF(G3=0,100,100-(100/(1+H3))) -> 67.672035
A4: 45727 | B4: 513.75 | C4: =B4-B5 -> 8.4 | D4: =IF(C4>0,C4,0) -> 8.4 | E4: =IF(C4>0,0,ABS(C4)) -> 0 | F4: =AVERAGE(D4:D17) -> 9.1821429 | G4: =AVERAGE(E4:E17) -> 3.9428571 | H4: =F4/G4 -> 2.3288043 | I4: =IF(G4=0,100,100-(100/(1+H4))) -> 69.959184
A5: 45726 | B5: 505.35 | C5: =B5-B6 -> 13.65 | D5: =IF(C5>0,C5,0) -> 13.65 | E5: =IF(C5>0,0,ABS(C5)) -> 0 | F5: =AVERAGE(D5:D18) -> 9.2178571 | G5: =AVERAGE(E5:E18) -> 3.9428571 | H5: =F5/G5 -> 2.3378623 | I5: =IF(G5=0,100,100-(100/(1+H5))) -> 70.040706
A6: 45723 | B6: 491.7 | C6: =B6-B7 -> -7.9 | D6: =IF(C6>0,C6,0) -> 0 | E6: =IF(C6>0,0,ABS(C6)) -> 7.9 | F6: =AVERAGE(D6:D19) -> 8.2428571 | G6: =AVERAGE(E6:E19) -> 4.3428571 | H6: =F6/G6 -> 1.8980263 | I6: =IF(G6=0,100,100-(100/(1+H6))) -> 65.493757
A7: 45722 | B7: 499.6 | C7: =B7-B8 -> -9.5 | D7: =IF(C7>0,C7,0) -> 0 | E7: =IF(C7>0,0,ABS(C7)) -> 9.5 | F7: =AVERAGE(D7:D20) -> 8.2428571 | G7: =AVERAGE(E7:E20) -> 5.9607143 | H7: =F7/G7 -> 1.382864 | I7: =IF(G7=0,100,100-(100/(1+H7))) -> 58.033694
A8: 45721 | B8: 509.1 | C8: =B8-B9 -> 27.85 | D8: =IF(C8>0,C8,0) -> 27.85 | E8: =IF(C8>0,0,ABS(C8)) -> 0 | F8: =AVERAGE(D8:D21) -> 8.2464286 | G8: =AVERAGE(E8:E21) -> 5.2821429 | H8: =F8/G8 -> 1.56119 | I8: =IF(G8=0,100,100-(100/(1+H8))) -> 60.955649 | L8: RSI= 100-(100/1+RS)) = | M8: =AVERAGE(I2:I234) -> 48.860759
A9: 45720 | B9: 481.25 | C9: =B9-B10 -> 7.4 | D9: =IF(C9>0,C9,0) -> 7.4 | E9: =IF(C9>0,0,ABS(C9)) -> 0 | F9: =AVERAGE(D9:D22) -> 6.3071429 | G9: =AVERAGE(E9:E22) -> 5.2821429 | H9: =F9/G9 -> 1.19405 | I9: =IF(G9=0,100,100-(100/(1+H9))) -> 54.422188 | L9: RS-= Average gain/Average Loss = | M9: =AVERAGE(H2:H234) -> 1.2175763
A10: 45719 | B10: 473.85 | C10: =B10-B11 -> 9.75 | D10: =IF(C10>0,C10,0) -> 9.75 | E10: =IF(C10>0,0,ABS(C10)) -> 0 | F10: =AVERAGE(D10:D23) -> 5.7785714 | G10: =AVERAGE(E10:E23) -> 5.9964286 | H10: =F10/G10 -> 0.96366885 | I10: =IF(G10=0,100,100-(100/(1+H10))) -> 49.074917 | L10: Input Period= 14
A11: 45716 | B11: 464.1 | C11: =B11-B12 -> 5.3 | D11: =IF(C11>0,C11,0) -> 5.3 | E11: =IF(C11>0,0,ABS(C11)) -> 0 | F11: =AVERAGE(D11:D24) -> 5.0821429 | G11: =AVERAGE(E11:E24) -> 6.55 | H11: =F11/G11 -> 0.77589967 | I11: =IF(G11=0,100,100-(100/(1+H11))) -> 43.690513
A12: 45715 | B12: 458.8 | C12: =B12-B13 -> -8.45 | D12: =IF(C12>0,C12,0) -> 0 | E12: =IF(C12>0,0,ABS(C12)) -> 8.45 | F12: =AVERAGE(D12:D25) -> 4.7035714 | G12: =AVERAGE(E12:E25) -> 7.2321429 | H12: =F12/G12 -> 0.65037037 | I12: =IF(G12=0,100,100-(100/(1+H12))) -> 39.40754
A13: 45713 | B13: 467.25 | C13: =B13-B14 -> -12.45 | D13: =IF(C13>0,C13,0) -> 0 | E13: =IF(C13>0,0,ABS(C13)) -> 12.45 | F13: =AVERAGE(D13:D26) -> 4.7321429 | G13: =AVERAGE(E13:E26) -> 6.6285714 | H13: =F13/G13 -> 0.71390086 | I13: =IF(G13=0,100,100-(100/(1+H13))) -> 41.653568
A14: 45712 | B14: 479.7 | C14: =B14-B15 -> -16.9 | D14: =IF(C14>0,C14,0) -> 0 | E14: =IF(C14>0,0,ABS(C14)) -> 16.9 | F14: =AVERAGE(D14:D27) -> 6.4535714 | G14: =AVERAGE(E14:E27) -> 5.7392857 | H14: =F14/G14 -> 1.1244555 | I14: =IF(G14=0,100,100-(100/(1+H14))) -> 52.929115
A15: 45709 | B15: 496.6 | C15: =B15-B16 -> 28.05 | D15: =IF(C15>0,C15,0) -> 28.05 | E15: =IF(C15>0,0,ABS(C15)) -> 0 | F15: =AVERAGE(D15:D28) -> 8.1714286 | G15: =AVERAGE(E15:E28) -> 4.5321429 | H15: =F15/G15 -> 1.8029945 | I15: =IF(G15=0,100,100-(100/(1+H15))) -> 64.323868
A16: 45708 | B16: 468.55 | C16: =B16-B17 -> 13.7 | D16: =IF(C16>0,C16,0) -> 13.7 | E16: =IF(C16>0,0,ABS(C16)) -> 0 | F16: =AVERAGE(D16:D29) -> 6.1678571 | G16: =AVERAGE(E16:E29) -> 6.4142857 | H16: =F16/G16 -> 0.96158129 | I16: =IF(G16=0,100,100-(100/(1+H16))) -> 49.020721
A17: 45707 | B17: 454.85 | C17: =B17-B18 -> 14.45 | D17: =IF(C17>0,C17,0) -> 14.45 | E17: =IF(C17>0,0,ABS(C17)) -> 0 | F17: =AVERAGE(D17:D30) -> 5.1892857 | G17: =AVERAGE(E17:E30) -> 9.0285714 | H17: =F17/G17 -> 0.57476266 | I17: =IF(G17=0,100,100-(100/(1+H17))) -> 36.498367
A18: 45706 | B18: 440.4 | C18: =B18-B19 -> 8.9 | D18: =IF(C18>0,C18,0) -> 8.9 | E18: =IF(C18>0,0,ABS(C18)) -> 0 | F18: =AVERAGE(D18:D31) -> 5.925 | G18: =AVERAGE(E18:E31) -> 9.0285714 | H18: =F18/G18 -> 0.65625 | I18: =IF(G18=0,100,100-(100/(1+H18))) -> 39.622642
A19: 45705 | B19: 431.5 | C19: =B19-B20 -> -5.6 | D19: =IF(C19>0,C19,0) -> 0 | E19: =IF(C19>0,0,ABS(C19)) -> 5.6 | F19: =AVERAGE(D19:D32) -> 5.9392857 | G19: =AVERAGE(E19:E32) -> 9.0285714 | H19: =F19/G19 -> 0.65783228 | I19: =IF(G19=0,100,100-(100/(1+H19))) -> 39.680267
A20: 45702 | B20: 437.1 | C20: =B20-B21 -> -30.55 | D20: =IF(C20>0,C20,0) -> 0 | E20: =IF(C20>0,0,ABS(C20)) -> 30.55 | F20: =AVERAGE(D20:D33) -> 5.9392857 | G20: =AVERAGE(E20:E33) -> 10.717857 | H20: =F20/G20 -> 0.55414862 | I20: =IF(G20=0,100,100-(100/(1+H20))) -> 35.656089
A21: 45701 | B21: 467.65 | C21: =B21-B22 -> 0.05 | D21: =IF(C21>0,C21,0) -> 0.05 | E21: =IF(C21>0,0,ABS(C21)) -> 0 | F21: =AVERAGE(D21:D34) -> 5.9392857 | G21: =AVERAGE(E21:E34) -> 10.703571 | H21: =F21/G21 -> 0.55488822 | I21: =IF(G21=0,100,100-(100/(1+H21))) -> 35.686695
A22: 45700 | B22: 467.6 | C22: =B22-B23 -> 0.7 | D22: =IF(C22>0,C22,0) -> 0.7 | E22: =IF(C22>0,0,ABS(C22)) -> 0 | F22: =AVERAGE(D22:D35) -> 5.9357143 | G22: =AVERAGE(E22:E35) -> 11.403571 | H22: =F22/G22 -> 0.52051362 | I22: =IF(G22=0,100,100-(100/(1+H22))) -> 34.23275
... A234: 45391 | B234: 613.1 | C234: =B234-B235 -> -14.4 | D234: =IF(C234>0,C234,0) -> 0 | E234: =IF(C234>0,0,ABS(C234)) -> 14.4 | F234: =AVERAGE(D234:D247) -> 11.242857 | G234: =AVERAGE(E234:E247) -> 2.8357143 | H234: =F234/G234 -> 3.9647355 | I234: =IF(G234=0,100,100-(100/(1+H234))) -> 79.85794
A235: 45390 | B235: 627.5 | C235: =B235-B236 -> 28.4 | D235: =IF(C235>0,C235,0) -> 28.4 | E235: =IF(C235>0,0,ABS(C235)) -> 0
A236: 45387 | B236: 599.1 | C236: =B236-B237 -> 16.05 | D236: =IF(C236>0,C236,0) -> 16.05 | E236: =IF(C236>0,0,ABS(C236)) -> 0
A237: 45386 | B237: 583.05 | C237: =B237-B238 -> 1.7 | D237: =IF(C237>0,C237,0) -> 1.7 | E237: =IF(C237>0,0,ABS(C237)) -> 0
A238: 45385 | B238: 581.35 | C238: =B238-B239 -> 39.15 | D238: =IF(C238>0,C238,0) -> 39.15 | E238: =IF(C238>0,0,ABS(C238)) -> 0
A239: 45384 | B239: 542.2 | C239: =B239-B240 -> 23.75 | D239: =IF(C239>0,C239,0) -> 23.75 | E239: =IF(C239>0,0,ABS(C239)) -> 0
A240: 45383 | B240: 518.45 | C240: =B240-B241 -> -10.45 | D240: =IF(C240>0,C240,0) -> 0 | E240: =IF(C240>0,0,ABS(C240)) -> 10.45
A241: 45379 | B241: 528.9 | C241: =B241-B242 -> 12.25 | D241: =IF(C241>0,C241,0) -> 12.25 | E241: =IF(C241>0,0,ABS(C241)) -> 0
A242: 45378 | B242: 516.65 | C242: =B242-B243 -> 3.45 | D242: =IF(C242>0,C242,0) -> 3.45 | E242: =IF(C242>0,0,ABS(C242)) -> 0
A243: 45377 | B243: 513.2 | C243: =B243-B244 -> -2.25 | D243: =IF(C243>0,C243,0) -> 0 | E243: =IF(C243>0,0,ABS(C243)) -> 2.25
A244: 45373 | B244: 515.45 | C244: =B244-B245 -> 10.9 | D244: =IF(C244>0,C244,0) -> 10.9 | E244: =IF(C244>0,0,ABS(C244)) -> 0
A245: 45372 | B245: 504.55 | C245: =B245-B246 -> 15.4 | D245: =IF(C245>0,C245,0) -> 15.4 | E245: =IF(C245>0,0,ABS(C245)) -> 0
A246: 45371 | B246: 489.15 | C246: =B246-B247 -> 6.35 | D246: =IF(C246>0,C246,0) -> 6.35 | E246: =IF(C246>0,0,ABS(C246)) -> 0
A247: 45370 | B247: 482.8 | C247: =B247-B248 -> -12.6 | D247: =IF(C247>0,C247,0) -> 0 | E247: =IF(C247>0,0,ABS(C247)) -> 12.6
A248: 45369 | B248: 495.4

Sheet MACD
A1: Date | B1: close | C1: 12 Day EMA | D1: 26 day EMA | E1: MACD line | F1: Signal line | G1: Histogram
A2: 45729 | B2: 514.1 | C2: =((B2-C3)*$O$9)+C3 -> 600.5344 | D2: =((C2-D3)*$O$9)+D3 -> 610.6859 | E2: =C2-D2 -> -10.151497 | F2: =((E2-F3)*$O$9+F3) -> 15.805563 | G2: =E2-F2 -> -25.95706
A3: 45728 | B3: 515.2 | C3: =((B3-C4)*$O$9)+C4 -> 601.23712 | D3: =((C3-D4)*$O$9)+D4 -> 610.76843 | E3: =C3-D3 -> -9.5313105 | F3: =((E3-F4)*$O$9+F4) -> 16.016596 | G3: =E3-F3 -> -25.547907
A4: 45727 | B4: 513.75 | C4: =((B4-C5)*$O$9)+C5 -> 601.93661 | D4: =((C4-D5)*$O$9)+D5 -> 610.84592 | E4: =C4-D4 -> -8.9093121 | F4: =((E4-F5)*$O$9+F5) -> 16.224303 | G4: =E4-F4 -> -25.133615
A5: 45726 | B5: 505.35 | C5: =((B5-C6)*$O$9)+C6 -> 602.65357 | D5: =((C5-D6)*$O$9)+D6 -> 610.91835 | E5: =C5-D5 -> -8.2647813 | F5: =((E5-F6)*$O$9+F6) -> 16.428641 | G5: =E5-F5 -> -24.693422 | O5: MACD Line: (12 day EMA -26 day EMA )
A6: 45723 | B6: 491.7 | C6: =((B6-C7)*$O$9)+C7 -> 603.44466 | D6: =((C6-D7)*$O$9)+D7 -> 610.98555 | E6: =C6-D6 -> -7.5408887 | F6: =((E6-F7)*$O$9+F7) -> 16.629401 | G6: =E6-F6 -> -24.170289 | O6: Signal line: 9-day EMA of MACD line
A7: 45722 | B7: 499.6 | C7: =((B7-C8)*$O$9)+C8 -> 604.35315 | D7: =((C7-D8)*$O$9)+D8 -> 611.04685 | E7: =C7-D7 -> -6.6937035 | F7: =((E7-F8)*$O$9+F8) -> 16.825907 | G7: =E7-F7 -> -23.519611 | O7: MACD Histogram: MACD line- Signal line
A8: 45721 | B8: 509.1 | C8: =((B8-C9)*$O$9)+C9 -> 605.2048 | D8: =((C8-D9)*$O$9)+D9 -> 611.10127 | E8: =C8-D8 -> -5.8964723 | F8: =((E8-F9)*$O$9+F9) -> 17.017124 | G8: =E8-F8 -> -22.913596
A9: 45720 | B9: 481.25 | C9: =((B9-C10)*$O$9)+C10 -> 605.98614 | D9: =((C9-D10)*$O$9)+D10 -> 611.14921 | E9: =C9-D9 -> -5.1630712 | F9: =((E9-F10)*$O$9+F10) -> 17.203413 | G9: =E9-F9 -> -22.366484 | N9: multiplier | O9: =2/(COUNT(B2:B248)+1) -> 0.0080645161
A10: 45719 | B10: 473.85 | C10: =((B10-C11)*$O$9)+C11 -> 607.00026 | D10: =((C10-D11)*$O$9)+D11 -> 611.19119 | E10: =C10-D10 -> -4.1909324 | F10: =((E10-F11)*$O$9+F11) -> 17.385254 | G10: =E10-F10 -> -21.576187
A11: 45716 | B11: 464.1 | C11: =((B11-C12)*$O$9)+C12 -> 608.08278 | D11: =((C11-D12)*$O$9)+D12 -> 611.22526 | E11: =C11-D11 -> -3.1424826 | F11: =((E11-F12)*$O$9+F12) -> 17.56067 | G11: =E11-F11 -> -20.703153
A12: 45715 | B12: 458.8 | C12: =((B12-C13)*$O$9)+C13 -> 609.25337 | D12: =((C12-D13)*$O$9)+D13 -> 611.25081 | E12: =C12-D12 -> -1.9974396 | F12: =((E12-F13)*$O$9+F13) -> 17.728989 | G12: =E12-F12 -> -19.726428
A13: 45713 | B13: 467.25 | C13: =((B13-C14)*$O$9)+C14 -> 610.47657 | D13: =((C13-D14)*$O$9)+D14 -> 611.26705 | E13: =C13-D13 -> -0.7904808 | F13: =((E13-F14)*$O$9+F14) -> 17.889366 | G13: =E13-F13 -> -18.679847
A14: 45712 | B14: 479.7 | C14: =((B14-C15)*$O$9)+C15 -> 611.64101 | D14: =((C14-D15)*$O$9)+D15 -> 611.27348 | E14: =C14-D14 -> 0.36753618 | F14: =((E14-F15)*$O$9+F15) -> 18.041235 | G14: =E14-F14 -> -17.673699 | L14: 12 day EMA | M14: =AVERAGE(C2:C237) -> 601.13751
A15: 45709 | B15: 496.6 | C15: =((B15-C16)*$O$9)+C16 -> 612.7137 | D15: =((C15-D16)*$O$9)+D16 -> 611.27049 | E15: =C15-D15 -> 1.4432154 | F15: =((E15-F16)*$O$9+F16) -> 18.184923 | G15: =E15-F15 -> -16.741708 | L15: 26 day EMA | M15: =AVERAGE(D2:D223) -> 583.9397
A16: 45708 | B16: 468.55 | C16: =((B16-C17)*$O$9)+C17 -> 613.65772 | D16: =((C16-D17)*$O$9)+D17 -> 611.25875 | E16: =C16-D16 -> 2.3989627 | F16: =((E16-F17)*$O$9+F17) -> 18.321035 | G16: =E16-F16 -> -15.922072 | L16: MACD line | M16: =AVERAGE(E2:E223) -> 21.858492
A17: 45707 | B17: 454.85 | C17: =((B17-C18)*$O$9)+C18 -> 614.83745 | D17: =((C17-D18)*$O$9)+D18 -> 611.23925 | E17: =C17-D17 -> 3.598204 | F17: =((E17-F18)*$O$9+F18) -> 18.450483 | G17: =E17-F17 -> -14.852279 | L17: Signal line | M17: =AVERAGE(F2:F215) -> -5.1864999
A18: 45706 | B18: 440.4 | C18: =((B18-C19)*$O$9)+C19 -> 616.13817 | D18: =((C18-D19)*$O$9)+D19 -> 611.21 | E18: =C18-D18 -> 4.9281687 | F18: =((E18-F19)*$O$9+F19) -> 18.571233 | G18: =E18-F18 -> -13.643064 | L18: MACD Histogram | M18: =AVERAGE(G2:G215) -> 29.18108
A19: 45705 | B19: 431.5 | C19: =((B19-C20)*$O$9)+C20 -> 617.56693 | D19: =((C19-D20)*$O$9)+D20 -> 611.16993 | E19: =C19-D19 -> 6.3970007 | F19: =((E19-F20)*$O$9+F20) -> 18.682152 | G19: =E19-F19 -> -12.285151
A20: 45702 | B20: 437.1 | C20: =((B20-C21)*$O$9)+C21 -> 619.07967 | D20: =((C20-D21)*$O$9)+D21 -> 611.11792 | E20: =C20-D20 -> 7.9617482 | F20: =((E20-F21)*$O$9+F21) -> 18.782031 | G20: =E20-F20 -> -10.820283
A21: 45701 | B21: 467.65 | C21: =((B21-C22)*$O$9)+C22 -> 620.55918 | D21: =((C21-D22)*$O$9)+D22 -> 611.05319 | E21: =C21-D21 -> 9.5059873 | F21: =((E21-F22)*$O$9+F22) -> 18.870001 | G21: =E21-F21 -> -9.3640138
A22: 45700 | B22: 467.6 | C22: =((B22-C23)*$O$9)+C23 -> 621.80234 | D22: =((C22-D23)*$O$9)+D23 -> 610.97591 | E22: =C22-D22 -> 10.826436 | F22: =((E22-F23)*$O$9+F23) -> 18.946131 | G22: =E22-F22 -> -8.1196955
A23: 45699 | B23: 466.9 | C23: =((B23-C24)*$O$9)+C24 -> 623.05602 | D23: =((C23-D24)*$O$9)+D24 -> 610.88789 | E23: =C23-D23 -> 12.168133 | F23: =((E23-F24)*$O$9+F24) -> 19.012145 | G23: =E23-F23 -> -6.8440119
A24: 45698 | B24: 476.9 | C24: =((B24-C25)*$O$9)+C25 -> 624.32558 | D24: =((C24-D25)*$O$9)+D25 -> 610.78896 | E24: =C24-D24 -> 13.536622 | F24: =((E24-F25)*$O$9+F25) -> 19.067788 | G24: =E24-F24 -> -5.5311652
A25: 45695 | B25: 484.65 | C25: =((B25-C26)*$O$9)+C26 -> 625.52417 | D25: =((C25-D26)*$O$9)+D26 -> 610.67891 | E25: =C25-D25 -> 14.845258 | F25: =((E25-F26)*$O$9+F26) -> 19.112756 | G25: =E25-F25 -> -4.2674982
A26: 45694 | B26: 494.2 | C26: =((B26-C27)*$O$9)+C27 -> 626.66948 | D26: =((C26-D27)*$O$9)+D27 -> 610.55821 | E26: =C26-D26 -> 16.11127 | F26: =((E26-F27)*$O$9+F27) -> 19.147451 | G26: =E26-F26 -> -3.0361817
A27: 45693 | B27: 493.8 | C27: =((B27-C28)*$O$9)+C28 -> 627.74647 | D27: =((C27-D28)*$O$9)+D28 -> 610.42723 | E27: =C27-D27 -> 17.319243 | F27: =((E27-F28)*$O$9+F28) -> 19.172136 | G27: =E27-F27 -> -1.8528925
A28: 45692 | B28: 469.7 | C28: =((B28-C29)*$O$9)+C29 -> 628.83547 | D28: =((C28-D29)*$O$9)+D29 -> 610.28642 | E28: =C28-D28 -> 18.549046 | F28: =((E28-F29)*$O$9+F29) -> 19.1872 | G28: =E28-F28 -> -0.63815416
A29: 45691 | B29: 445.65 | C29: =((B29-C30)*$O$9)+C30 -> 630.12925 | D29: =((C29-D30)*$O$9)+D30 -> 610.13562 | E29: =C29-D29 -> 19.993635 | F29: =((E29-F30)*$O$9+F30) -> 19.192388 | G29: =E29-F29 -> 0.80124713
A30: 45689 | B30: 472 | C30: =((B30-C31)*$O$9)+C31 -> 631.62908 | D30: =((C30-D31)*$O$9)+D31 -> 609.97307 | E30: =C30-D30 -> 21.656017 | F30: =((E30-F31)*$O$9+F31) -> 19.185874 | G30: =E30-F30 -> 2.4701425
... A214: 45422 | B214: 570.25 | C214: =((B214-C215)*$O$9)+C215 -> 536.72029 | D214: =((C214-D215)*$O$9)+D215 -> 568.41948 | E214: =C214-D214 -> -31.699197 | F214: =((E214-F215)*$O$9+F215) -> -34.916555 | G214: =E214-F214 -> 3.2173588
A215: 45421 | B215: 530.95 | C215: =((B215-C216)*$O$9)+C216 -> 536.44769 | D215: =((C215-D216)*$O$9)+D216 -> 568.6772 | E215: =C215-D215 -> -32.229513 | F215: =AVERAGE(E215:E223) -> -34.942713 | G215: =E215-F215 -> 2.7131998
A216: 45420 | B216: 557.25 | C216: =((B216-C217)*$O$9)+C217 -> 536.49238 | D216: =((C216-D217)*$O$9)+D217 -> 568.93923 | E216: =C216-D216 -> -32.446845
A217: 45419 | B217: 584.05 | C217: =((B217-C218)*$O$9)+C218 -> 536.32362 | D217: =((C217-D218)*$O$9)+D218 -> 569.20302 | E217: =C217-D217 -> -32.879401
A218: 45418 | B218: 617.55 | C218: =((B218-C219)*$O$9)+C219 -> 535.9356 | D218: =((C218-D219)*$O$9)+D219 -> 569.47034 | E218: =C218-D218 -> -33.534733
A219: 45415 | B219: 642.2 | C219: =((B219-C220)*$O$9)+C220 -> 535.27207 | D219: =((C219-D220)*$O$9)+D220 -> 569.74298 | E219: =C219-D219 -> -34.470905
A220: 45414 | B220: 638.25 | C220: =((B220-C221)*$O$9)+C221 -> 534.40274 | D220: =((C220-D221)*$O$9)+D221 -> 570.02323 | E220: =C220-D220 -> -35.620489
A221: 45412 | B221: 629.55 | C221: =((B221-C222)*$O$9)+C222 -> 533.55845 | D221: =((C221-D222)*$O$9)+D222 -> 570.31282 | E221: =C221-D221 -> -36.754373
A222: 45411 | B222: 603.3 | C222: =((B222-C223)*$O$9)+C223 -> 532.77803 | D222: =((C222-D223)*$O$9)+D223 -> 570.61164 | E222: =C222-D222 -> -37.833608
A223: 45408 | B223: 600.9 | C223: =((B223-C224)*$O$9)+C224 -> 532.20468 | D223: =AVERAGE(B223:B248) -> 570.91923 | E223: =C223-D223 -> -38.714548
...

Sheet Balance Sheet
A1: Balance Sheet of JSW Energy (in Rs. Cr.) | B1: Mar-24 | C1: Mar-23 | D1: Mar-22 | E1: Mar-21 | F1: Mar-20
B2: 12 mths | C2: 12 mths | D2: 12 mths | E2: 12 mths | F2: 12 mths
A3: EQUITIES AND LIABILITIES
A4: SHAREHOLDER'S FUNDS
A5: Equity Share Capital | B5: 1641.22 | C5: 1640.54 | D5: 1639.67 | E5: 1642.33 | F5: 1641.9
A6: Total Share Capital | B6: 1641.22 | C6: 1640.54 | D6: 1639.67 | E6: 1642.33 | F6: 1641.9
A7: Reserves and Surplus | B7: 13470.83 | C7: 11968.87 | D7: 11848.04 | E7: 9990.01 | F7: 7758.3
A8: Total Reserves and Surplus | B8: 13470.83 | C8: 11968.87 | D8: 11848.04 | E8: 9990.01 | F8: 7758.3
A9: Total Shareholders Funds | B9: 15112.05 | C9: 13609.41 | D9: 13487.71 | E9: 11632.34 | F9: 9400.2
A10: NON-CURRENT LIABILITIES
A11: Long Term Borrowings | B11: 4441.46 | C11: 3136.36 | D11: 674.94 | E11: 710.51 | F11: 1333.08
A12: Deferred Tax Liabilities [Net] | B12: 1104.43 | C12: 967.5 | D12: 841.95 | E12: 559.17 | F12: 325.9
A13: Other Long Term Liabilities | B13: 19.69 | C13: 24.67 | D13: 9.86 | E13: 7.35 | F13: 6.51
A14: Long Term Provisions | B14: 23.81 | C14: 22.22 | D14: 29.8 | E14: 22.26 | F14: 19.9
A15: Total Non-Current Liabilities | B15: 5589.39 | C15: 4150.75 | D15: 1556.55 | E15: 1299.29 | F15: 1685.39
A16: CURRENT LIABILITIES
A17: Short Term Borrowings | B17: 2563.52 | C17: 3137.26 | D17: 596.74 | E17: 199.35 | F17: 0
A18: Trade Payables | B18: 1011.36 | C18: 900.51 | D18: 883.99 | E18: 717.68 | F18: 1265.91
A19: Other Current Liabilities | B19: 324.33 | C19: 142.64 | D19: 141.07 | E19: 861.78 | F19: 1199.73
A20: Short Term Provisions | B20: 9.23 | C20: 8.89 | D20: 6.38 | E20: 5.87 | F20: 4.21
A21: Total Current Liabilities | B21: 3908.44 | C21: 4189.3 | D21: 1628.18 | E21: 1784.68 | F21: 2469.85
A22: Total Capital And Liabilities | B22: 24609.88 | C22: 21949.46 | D22: 16672.44 | E22: 14716.31 | F22: 13555.44
A23: TOTAL LIABILITIES | B23: =B15+B21 -> 9497.83 | C23: =C15+C21 -> 8340.05 | D23: =D15+D21 -> 3184.73 | E23: =E15+E21 -> 3083.97 | F23: =F15+F21 -> 4155.24
A24: TOTAL DEBT | B24: =B11+B17 -> 7004.98 | C24: =C11+C17 -> 6273.62 | D24: =D11+D17 -> 1271.68 | E24: =E11+E17 -> 909.86 | F24: =F11+F17 -> 1333.08
A25: ASSETS
A26: NON-CURRENT ASSETS
A27: Tangible Assets | B27: 3509.64 | C27: 3706.42 | D27: 3954.46 | E27: 4178.9 | F27: 4507.17
A28: Intangible Assets | B28: 1.71 | C28: 2.21 | D28: 2.2 | E28: 1.22 | F28: 0.76
A29: Capital Work-In-Progress | B29: 17.56 | C29: 15.53 | D29: 23.44 | E29: 33.85 | F29: 108.85
A30: Other Assets | B30: 0 | C30: 0 | D30: 0 | E30: 0 | F30: 0
A31: Fixed Assets | B31: 3531.7 | C31: 3724.16 | D31: 3980.1 | E31: 4213.97 | F31: 4616.78
A32: Non-Current Investments | B32: 17335.47 | C32: 14654.68 | D32: 6654.04 | E32: 7674.34 | F32: 5082.7
A33: Deferred Tax Assets [Net] | B33: 0 | C33: 0 | D33: 0 | E33: 0 | F33: 0
A34: Long Term Loans And Advances | B34: 80.97 | C34: 79.85 | D34: 73.62 | E34: 102.53 | F34: 205.13
A35: Other Non-Current Assets | B35: 1401.72 | C35: 1255.27 | D35: 1213.37 | E35: 1179.08 | F35: 1160.44
A36: Total Non-Current Assets | B36: 22349.86 | C36: 19713.96 | D36: 11921.13 | E36: 13169.92 | F36: 11065.05
A37: CURRENT ASSETS
A38: Current Investments | B38: 77.97 | C38: 75.82 | D38: 212.6 | E38: 537.56 | F38: 334.1
A39: Inventories | B39: 439.13 | C39: 781.86 | D39: 776.09 | E39: 236.34 | F39: 540.77
A40: Trade Receivables | B40: 623.75 | C40: 644.73 | D40: 300.51 | E40: 253 | F40: 797.12
...

Sheet Income Statement
A1: JSW Energy Income Statement | B1: Mar 24 | C1: Mar-23 | D1: Mar-22 | E1: Mar-21 | F1: Mar-20
B2: 12 mths | C2: 12 mths | D2: 12 mths | E2: 12 mths | F2: 12 mths
A3: INCOME
A4: Revenue From Operations [Gross] | B4: 5110.15 | C4: 5728.93 | D4: 3634.29 | E4: 2883.73 | F4: 4298
A5: Revenue From Operations [Net] | B5: 5110.15 | C5: 5728.93 | D5: 3634.29 | E5: 2883.73 | F5: 4298
A6: Other Operating Revenues | B6: 18.94 | C6: 10.3 | D6: 8.45 | E6: 13.8 | F6: 15.99
A7: Total Operating Revenues | B7: 5129.09 | C7: 5739.23 | D7: 3642.74 | E7: 2897.53 | F7: 4313.99
A8: Other Income | B8: 210.4 | C8: 279.85 | D8: 228.26 | E8: 62.41 | F8: 197.9
A9: Total Revenue | B9: 5339.49 | C9: 6019.08 | D9: 3871 | E9: 2959.94 | F9: 4511.89
A10: EXPENSES
A11: Purchase Of Stock-In Trade | B11: 117.16 | C11: 354.45 | D11: 26.11 | E11: 0 | F11: 0
A12: Cost Of Fuel | B12: 2730.82 | C12: 3643.63 | D12: 2041.09 | E12: 1778.14 | F12: 3074.4
A13: Employee Benefit Expenses | B13: 153.23 | C13: 134.73 | D13: 124.1 | E13: 112.32 | F13: 118.71
A14: Finance Costs | B14: 477.87 | C14: 259.8 | D14: 127 | E14: 210.1 | F14: 321.95
A15: Depreciation And Amortisation Expenses | B15: 269.54 | C15: 317.42 | D15: 327.69 | E15: 358.07 | F15: 369.27
A16: Other Expenses | B16: 409.56 | C16: 399.44 | D16: 406.93 | E16: 193.57 | F16: 226.71
A17: Total Expenses | B17: 4158.18 | C17: 5109.47 | D17: 3052.92 | E17: 2652.2 | F17: 4111.04
A18: NET INCOME | B18: =B9-B17 -> 1181.31 | C18: =C9-C17 -> 909.61 | D18: =D9-D17 -> 818.08 | E18: =E9-E17 -> 307.74 | F18: =F9-F17 -> 400.85
A19: NET SALES | B19: 1235.97 | C19: 1646.64 | D19: 2440.86 | E19: 1569.62 | F19: 1848
B20: 45352 | C20: 44986 | D20: 44621 | E20: 44256 | F20: 43891
B21: 12 mths | C21: 12 mths | D21: 12 mths | E21: 12 mths | F21: 12 mths
A22: Profit/Loss Before Exceptional, ExtraOrdinary Items And Tax | B22: 1181.31 | C22: 909.61 | D22: 818.08 | E22: 307.74 | F22: 400.85
A23: Exceptional Items | B23: 0 | C23: 120 | D23: 0 | E23: 0 | F23: 23.02
A24: Profit/Loss Before Tax | B24: 1181.31 | C24: 1029.61 | D24: 818.08 | E24: 307.74 | F24: 423.87
A25: Tax Expenses-Continued Operations
A26: Current Tax | B26: 209.99 | C26: 156.7 | D26: 174.87 | E26: 40.15 | F26: 5.5
A27: Deferred Tax | B27: 21.1 | C27: 161.89 | D27: 73.39 | E27: 81.41 | F27: -79.44
A28: Total Tax Expenses | B28: 231.09 | C28: 318.59 | D28: 248.26 | E28: 121.56 | F28: -73.94
A29: Profit/Loss After Tax And Before ExtraOrdinary Items | B29: 950.22 | C29: 711.02 | D29: 569.82 | E29: 186.18 | F29: 497.81
A30: Profit/Loss From Continuing Operations | B30: 950.22 | C30: 711.02 | D30: 569.82 | E30: 186.18 | F30: 497.81
A31: Profit/Loss For The Period | B31: 950.22 | C31: 711.02 | D31: 569.82 | E31: 186.18 | F31: 497.81
B32: 45352 | C32: 44986 | D32: 44621 | E32: 44256 | F32: 43891
B33: 12 mths | C33: 12 mths | D33: 12 mths | E33: 12 mths | F33: 12 mths
A34: OTHER ADDITIONAL INFORMATION
A35: EARNINGS PER SHARE
A36: Basic EPS (Rs.) | B36: 5.79 | C36: 4.33 | D36: 3.47 | E36: 1.13 | F36: 3.03
A37: Diluted EPS (Rs.) | B37: 5.78 | C37: 4.33 | D37: 3.46 | E37: 1.13 | F37: 3.03
A38: VALUE OF IMPORTED AND INDIGENIOUS RAW MATERIALS
A39: STORES, SPARES AND LOOSE TOOLS
A40: DIVIDEND AND DIVIDEND PERCENTAGE
...

Sheet Horizontal analysis of P&L
A1: Column1 | B1: Column2 | C1: Column3 | D1: Column4 | E1: Column5 | F1: Column6 | H1: Horizontal Analysis Of Income Statement of JSWENERGY
A2: JSW Energy | B2: Previous Years �
A3: Income Statement | B3: ------------------- in Rs. Cr. -------------------
B4: Mar 24 | C4: 44986 | D4: 44621 | E4: 44256 | F4: 43891
B5: 12 mths | C5: 12 mths | D5: 12 mths | E5: 12 mths | F5: 12 mths | H5: =A6 -> INCOME | J5: 2021 | K5: 2022 | L5: 2023 | M5: 2024 | Q5: 2021 | R5: =AVERAGE(J6:J43) -> -0.23199539
A6: INCOME | H6: =A7 -> Revenue From Operations [Gross] | J6: =(E7-F7)/F7 -> -0.32905305 | K6: =(D7-F7)/F7 -> -0.15442299 | L6: =(C7-F7)/F7 -> 0.33292927 | M6: =(B7-F7)/F7 -> 0.18895998 | Q6: 2022 | R6: =AVERAGE(K6:K43) -> 0.92303644
A7: Revenue From Operations [Gross] | B7: 5110.15 | C7: 5728.93 | D7: 3634.29 | E7: 2883.73 | F7: 4298 | H7: =A8 -> Revenue From Operations [Net] | J7: =(E8-F8)/F8 -> -0.32905305 | K7: =(D8-F8)/F8 -> -0.15442299 | L7: =(C8-F8)/F8 -> 0.33292927 | M7: =(B8-F8)/F8 -> 0.18895998 | Q7: 2023 | R7: =AVERAGE(L6:L43) -> 1.1297027
A8: Revenue From Operations [Net] | B8: 5110.15 | C8: 5728.93 | D8: 3634.29 | E8: 2883.73 | F8: 4298 | H8: =A9 -> Other Operating Revenues | J8: =(E9-F9)/F9 -> -0.1369606 | K8: =(D9-F9)/F9 -> -0.47154472 | L8: =(C9-F9)/F9 -> -0.3558474 | M8: =(B9-F9)/F9 -> 0.18449031 | Q8: 2024 | R8: =AVERAGE(M6:M43) -> 1.512426
A9: Other Operating Revenues | B9: 18.94 | C9: 10.3 | D9: 8.45 | E9: 13.8 | F9: 15.99 | H9: =A10 -> Total Operating Revenues | J9: =(E10-F10)/F10 -> -0.32834105 | K9: =(D10-F10)/F10 -> -0.15559841 | L9: =(C10-F10)/F10 -> 0.33037629 | M9: =(B10-F10)/F10 -> 0.18894341
A10: Total Operating Revenues | B10: 5129.09 | C10: 5739.23 | D10: 3642.74 | E10: 2897.53 | F10: 4313.99 | H10: =A11 -> Other Income | J10: =(E11-F11)/F11 -> -0.68463871 | K10: =(D11-F11)/F11 -> 0.15341081 | L10: =(C11-F11)/F11 -> 0.41409803 | M10: =(B11-F11)/F11 -> 0.063163214
A11: Other Income | B11: 210.4 | C11: 279.85 | D11: 228.26 | E11: 62.41 | F11: 197.9 | H11: =A12 -> Total Revenue | J11: =(E12-F12)/F12 -> -0.34396894 | K11: =(D12-F12)/F12 -> -0.14204469 | L11: =(C12-F12)/F12 -> 0.33404848 | M11: =(B12-F12)/F12 -> 0.18342646
A12: Total Revenue | B12: 5339.49 | C12: 6019.08 | D12: 3871 | E12: 2959.94 | F12: 4511.89 | H12: =A13 -> EXPENSES
A13: EXPENSES | H13: =A14 -> Purchase Of Stock-In Trade
A14: Purchase Of Stock-In Trade | B14: 117.16 | C14: 354.45 | D14: 26.11 | E14: 0 | F14: 0 | H14: =A15 -> Cost Of Fuel | J14: =(E15-F15)/F15 -> -0.42163024 | K14: =(D15-F15)/F15 -> -0.33610135 | L14: =(C15-F15)/F15 -> 0.18515157 | M14: =(B15-F15)/F15 -> -0.11175514
A15: Cost Of Fuel | B15: 2730.82 | C15: 3643.63 | D15: 2041.09 | E15: 1778.14 | F15: 3074.4 | H15: =A16 -> Employee Benefit Expenses | J15: =(E16-F16)/F16 -> -0.053828658 | K15: =(D16-F16)/F16 -> 0.045404768 | L15: =(C16-F16)/F16 -> 0.13495072 | M15: =(B16-F16)/F16 -> 0.29079269
A16: Employee Benefit Expenses | B16: 153.23 | C16: 134.73 | D16: 124.1 | E16: 112.32 | F16: 118.71 | H16: =A17 -> Finance Costs | J16: =(E17-F17)/F17 -> -0.34741419 | K16: =(D17-F17)/F17 -> -0.60552881 | L16: =(C17-F17)/F17 -> -0.1930424 | M16: =(B17-F17)/F17 -> 0.4842988
A17: Finance Costs | B17: 477.87 | C17: 259.8 | D17: 127 | E17: 210.1 | F17: 321.95 | H17: =A18 -> Depreciation And Amortisation Expenses | J17: =(E18-F18)/F18 -> -0.030330111 | K17: =(D18-F18)/F18 -> -0.11260054 | L17: =(C18-F18)/F18 -> -0.14041216 | M17: =(B18-F18)/F18 -> -0.27007339
A18: Depreciation And Amortisation Expenses | B18: 269.54 | C18: 317.42 | D18: 327.69 | E18: 358.07 | F18: 369.27 | H18: =A19 -> Other Expenses | J18: =(E19-F19)/F19 -> -0.14617794 | K18: =(D19-F19)/F19 -> 0.79493626 | L18: =(C19-F19)/F19 -> 0.76189846 | M18: =(B19-F19)/F19 -> 0.80653699
A19: Other Expenses | B19: 409.56 | C19: 399.44 | D19: 406.93 | E19: 193.57 | F19: 226.71 | H19: =A20 -> Total Expenses | J19: =(E20-F20)/F20 -> -0.35485911 | K19: =(D20-F20)/F20 -> -0.25738499 | L19: =(C20-F20)/F20 -> 0.24286555 | M19: =(B20-F20)/F20 -> 0.011466685
A20: Total Expenses | B20: 4158.18 | C20: 5109.47 | D20: 3052.92 | E20: 2652.2 | F20: 4111.04 | H20: =A21 -> 0 | J20: =(E21-F21)/F21 -> 0.0083160557 | K20: =(D21-F21)/F21 -> 0.016632111 | L20: =(C21-F21)/F21 -> 0.024948167 | M20: =(B21-F21)/F21 -> 0.033287006
B21: 45352 | C21: 44986 | D21: 44621 | E21: 44256 | F21: 43891 | H21: =A22 -> 0
B22: 12 mths | C22: 12 mths | D22: 12 mths | E22: 12 mths | F22: 12 mths | H22: =A23 -> Profit/Loss Before Exceptional, ExtraOrdinary Items And Tax | J22: =(E23-F23)/F23 -> -0.2322814 | K22: =(D23-F23)/F23 -> 1.0408632 | L22: =(C23-F23)/F23 -> 1.2692029 | M22: =(B23-F23)/F23 -> 1.9470126
A23: Profit/Loss Before Exceptional, ExtraOrdinary Items And Tax | B23: 1181.31 | C23: 909.61 | D23: 818.08 | E23: 307.74 | F23: 400.85 | H23: =A24 -> Exceptional Items | J23: =(E24-F24)/F24 -> -1 | K23: =(D24-F24)/F24 -> -1 | L23: =(C24-F24)/F24 -> 4.2128584 | M23: =(B24-F24)/F24 -> -1
A24: Exceptional Items | B24: 0 | C24: 120 | D24: 0 | E24: 0 | F24: 23.02 | H24: =A25 -> Profit/Loss Before Tax | J24: =(E25-F25)/F25 -> -0.27397551 | K24: =(D25-F25)/F25 -> 0.93002572 | L24: =(C25-F25)/F25 -> 1.4290702 | M24: =(B25-F25)/F25 -> 1.786963
A25: Profit/Loss Before Tax | B25: 1181.31 | C25: 1029.61 | D25: 818.08 | E25: 307.74 | F25: 423.87 | H25: =A26 -> Tax Expenses-Continued Operations
A26: Tax Expenses-Continued Operations | H26: =A27 -> Current Tax | J26: =(E27-F27)/F27 -> 6.3 | K26: =(D27-F27)/F27 -> 30.794545 | L26: =(C27-F27)/F27 -> 27.490909 | M26: =(B27-F27)/F27 -> 37.18
A27: Current Tax | B27: 209.99 | C27: 156.7 | D27: 174.87 | E27: 40.15 | F27: 5.5 | H27: =A28 -> Deferred Tax | J27: =(E28-F28)/F28 -> -2.0247986 | K27: =(D28-F28)/F28 -> -1.9238419 | L27: =(C28-F28)/F28 -> -3.0378902 | M27: =(B28-F28)/F28 -> -1.2656093
A28: Deferred Tax | B28: 21.1 | C28: 161.89 | D28: 73.39 | E28: 81.41 | F28: -79.44 | H28: =A29 -> Total Tax Expenses | J28: =(E29-F29)/F29 -> -2.6440357 | K28: =(D29-F29)/F29 -> -4.3575872 | L28: =(C29-F29)/F29 -> -5.3087639 | M28: =(B29-F29)/F29 -> -4.1253719
A29: Total Tax Expenses | B29: 231.09 | C29: 318.59 | D29: 248.26 | E29: 121.56 | F29: -73.94 | H29: =A30 -> Profit/Loss After Tax And Before ExtraOrdinary Items | J29: =(E30-F30)/F30 -> -0.62600189 | K29: =(D30-F30)/F30 -> 0.14465358 | L29: =(C30-F30)/F30 -> 0.42829594 | M29: =(B30-F30)/F30 -> 0.90880055
A30: Profit/Loss After Tax And Before ExtraOrdinary Items | B30: 950.22 | C30: 711.02 | D30: 569.82 | E30: 186.18 | F30: 497.81 | H30: =A31 -> Profit/Loss From Continuing Operations | J30: =(E31-F31)/F31 -> -0.62600189 | K30: =(D31-F31)/F31 -> 0.14465358 | L30: =(C31-F31)/F31 -> 0.42829594 | M30: =(B31-F31)/F31 -> 0.90880055
A31: Profit/Loss From Continuing Operations | B31: 950.22 | C31: 711.02 | D31: 569.82 | E31: 186.18 | F31: 497.81 | H31: =A32 -> Profit/Loss For The Period | J31: =(E32-F32)/F32 -> -0.62600189 | K31: =(D32-F32)/F32 -> 0.14465358 | L31: =(C32-F32)/F32 -> 0.42829594 | M31: =(B32-F32)/F32 -> 0.90880055
A32: Profit/Loss For The Period | B32: 950.22 | C32: 711.02 | D32: 569.82 | E32: 186.18 | F32: 497.81 | H32: =A33 -> 0 | J32: =(E33-F33)/F33 -> 0.0083160557 | K32: =(D33-F33)/F33 -> 0.016632111 | L32: =(C33-F33)/F33 -> 0.024948167 | M32: =(B33-F33)/F33 -> 0.033287006
B33: 45352 | C33: 44986 | D33: 44621 | E33: 44256 | F33: 43891 | H33: =A34 -> 0
B34: 12 mths | C34: 12 mths | D34: 12 mths | E34: 12 mths | F34: 12 mths | H34: =A35 -> OTHER ADDITIONAL INFORMATION
A35: OTHER ADDITIONAL INFORMATION | H35: =A36 -> EARNINGS PER SHARE
A36: EARNINGS PER SHARE | H36: =A37 -> Basic EPS (Rs.) | J36: =(E37-F37)/F37 -> -0.62706271 | K36: =(D37-F37)/F37 -> 0.14521452 | L36: =(C37-F37)/F37 -> 0.4290429 | M36: =(B37-F37)/F37 -> 0.91089109
A37: Basic EPS (Rs.) | B37: 5.79 | C37: 4.33 | D37: 3.47 | E37: 1.13 | F37: 3.03 | H37: =A38 -> Diluted EPS (Rs.) | J37: =(E38-F38)/F38 -> -0.62706271 | K37: =(D38-F38)/F38 -> 0.14191419 | L37: =(C38-F38)/F38 -> 0.4290429 | M37: =(B38-F38)/F38 -> 0.90759076
A38: Diluted EPS (Rs.) | B38: 5.78 | C38: 4.33 | D38: 3.46 | E38: 1.13 | F38: 3.03 | H38: =A39 -> VALUE OF IMPORTED AND INDIGENIOUS RAW MATERIALS
A39: VALUE OF IMPORTED AND INDIGENIOUS RAW MATERIALS | H39: =A40 -> STORES, SPARES AND LOOSE TOOLS
A40: STORES, SPARES AND LOOSE TOOLS | H40: =A41 -> DIVIDEND AND DIVIDEND PERCENTAGE
...

Sheet Horizontal analysis of BS
A1: Balance Sheet of JSW Energy (in Rs. Cr.) | B1: Mar-24 | C1: Mar-23 | D1: Mar-22 | E1: Mar-21 | F1: Mar-20 | J1: Horizontal Analysis Of Balance Sheet of JSWENERGY
B2: 12 mths | C2: 12 mths | D2: 12 mths | E2: 12 mths | F2: 12 mths
A3: EQUITIES AND LIABILITIES
A4: SHAREHOLDER'S FUNDS | I4: SHAREHOLDER'S FUNDS | L4: 2021 | M4: 2022 | N4: 2023 | O4: 2024
A5: Equity Share Capital | B5: 1641.22 | C5: 1640.54 | D5: 1639.67 | E5: 1642.33 | F5: 1641.9 | I5: Equity Share Capital | L5: =(E5-F5)/F5 -> 0.00026189171 | M5: =(D5-F5)/F5 -> -0.0013581826 | N5: =(C5-F5)/F5 -> -0.00082830867 | O5: =(B5-F5)/F5 -> -0.00041415433 | R5: 2021 | S5: =AVERAGE(L5:L66) -> 0.010315244
A6: Total Share Capital | B6: 1641.22 | C6: 1640.54 | D6: 1639.67 | E6: 1642.33 | F6: 1641.9 | I6: Total Share Capital | L6: =(E6-F6)/F6 -> 0.00026189171 | M6: =(D6-F6)/F6 -> -0.0013581826 | N6: =(C6-F6)/F6 -> -0.00082830867 | O6: =(B6-F6)/F6 -> -0.00041415433 | R6: 2022 | S6: =AVERAGE(M5:M66) -> 0.44306577
A7: Reserves and Surplus | B7: 13470.83 | C7: 11968.87 | D7: 11848.04 | E7: 9990.01 | F7: 7758.3 | I7: Reserves and Surplus | L7: =(E7-F7)/F7 -> 0.28765451 | M7: =(D7-F7)/F7 -> 0.52714383 | N7: =(C7-F7)/F7 -> 0.54271812 | O7: =(B7-F7)/F7 -> 0.73631208 | R7: 2023 | S7: =AVERAGE(N5:N66) -> 20.800139
A8: Total Reserves and Surplus | B8: 13470.83 | C8: 11968.87 | D8: 11848.04 | E8: 9990.01 | F8: 7758.3 | I8: Total Reserves and Surplus | L8: =(E8-F8)/F8 -> 0.28765451 | M8: =(D8-F8)/F8 -> 0.52714383 | N8: =(C8-F8)/F8 -> 0.54271812 | O8: =(B8-F8)/F8 -> 0.73631208 | R8: 2024 | S8: =AVERAGE(O5:O66) -> 24.431212
A9: Total Shareholders Funds | B9: 15112.05 | C9: 13609.41 | D9: 13487.71 | E9: 11632.34 | F9: 9400.2 | I9: Total Shareholders Funds | L9: =(E9-F9)/F9 -> 0.23745665 | M9: =(D9-F9)/F9 -> 0.43483224 | N9: =(C9-F9)/F9 -> 0.44777877 | O9: =(B9-F9)/F9 -> 0.60763069
A10: NON-CURRENT LIABILITIES | I10: NON-CURRENT LIABILITIES
A11: Long Term Borrowings | B11: 4441.46 | C11: 3136.36 | D11: 674.94 | E11: 710.51 | F11: 1333.08 | I11: Long Term Borrowings | L11: =(E11-F11)/F11 -> -0.46701623 | M11: =(D11-F11)/F11 -> -0.4936988 | N11: =(C11-F11)/F11 -> 1.352717 | O11: =(B11-F11)/F11 -> 2.331728
A12: Deferred Tax Liabilities [Net] | B12: 1104.43 | C12: 967.5 | D12: 841.95 | E12: 559.17 | F12: 325.9 | I12: Deferred Tax Liabilities [Net] | L12: =(E12-F12)/F12 -> 0.71577171 | M12: =(D12-F12)/F12 -> 1.5834612 | N12: =(C12-F12)/F12 -> 1.9687021 | O12: =(B12-F12)/F12 -> 2.3888616
A13: Other Long Term Liabilities | B13: 19.69 | C13: 24.67 | D13: 9.86 | E13: 7.35 | F13: 6.51 | I13: Other Long Term Liabilities | L13: =(E13-F13)/F13 -> 0.12903226 | M13: =(D13-F13)/F13 -> 0.51459293 | N13: =(C13-F13)/F13 -> 2.7895545 | O13: =(B13-F13)/F13 -> 2.0245776
A14: Long Term Provisions | B14: 23.81 | C14: 22.22 | D14: 29.8 | E14: 22.26 | F14: 19.9 | I14: Long Term Provisions | L14: =(E14-F14)/F14 -> 0.11859296 | M14: =(D14-F14)/F14 -> 0.49748744 | N14: =(C14-F14)/F14 -> 0.11658291 | O14: =(B14-F14)/F14 -> 0.19648241
A15: Total Non-Current Liabilities | B15: 5589.39 | C15: 4150.75 | D15: 1556.55 | E15: 1299.29 | F15: 1685.39 | I15: Total Non-Current Liabilities | L15: =(E15-F15)/F15 -> -0.22908644 | M15: =(D15-F15)/F15 -> -0.076445214 | N15: =(C15-F15)/F15 -> 1.4627831 | O15: =(B15-F15)/F15 -> 2.3163778
A16: CURRENT LIABILITIES | I16: CURRENT LIABILITIES
A17: Short Term Borrowings | B17: 2563.52 | C17: 3137.26 | D17: 596.74 | E17: 199.35 | F17: 0 | I17: Short Term Borrowings
A18: Trade Payables | B18: 1011.36 | C18: 900.51 | D18: 883.99 | E18: 717.68 | F18: 1265.91 | I18: Trade Payables | L18: =(E18-F18)/F18 -> -0.43307186 | M18: =(D18-F18)/F18 -> -0.30169601 | N18: =(C18-F18)/F18 -> -0.28864611 | O18: =(B18-F18)/F18 -> -0.20108065
A19: Other Current Liabilities | B19: 324.33 | C19: 142.64 | D19: 141.07 | E19: 861.78 | F19: 1199.73 | I19: Other Current Liabilities | L19: =(E19-F19)/F19 -> -0.28168838 | M19: =(D19-F19)/F19 -> -0.88241521 | N19: =(C19-F19)/F19 -> -0.88110658 | O19: =(B19-F19)/F19 -> -0.72966417
A20: Short Term Provisions | B20: 9.23 | C20: 8.89 | D20: 6.38 | E20: 5.87 | F20: 4.21 | I20: Short Term Provisions | L20: =(E20-F20)/F20 -> 0.39429929 | M20: =(D20-F20)/F20 -> 0.51543943 | N20: =(C20-F20)/F20 -> 1.111639 | O20: =(B20-F20)/F20 -> 1.192399
A21: Total Current Liabilities | B21: 3908.44 | C21: 4189.3 | D21: 1628.18 | E21: 1784.68 | F21: 2469.85 | I21: Total Current Liabilities | L21: =(E21-F21)/F21 -> -0.27741361 | M21: =(D21-F21)/F21 -> -0.34077778 | N21: =(C21-F21)/F21 -> 0.69617588 | O21: =(B21-F21)/F21 -> 0.58246047
A22: Total Capital And Liabilities | B22: 24609.88 | C22: 21949.46 | D22: 16672.44 | E22: 14716.31 | F22: 13555.44 | I22: Total Capital And Liabilities | L22: =(E22-F22)/F22 -> 0.085638681 | M22: =(D22-F22)/F22 -> 0.22994458 | N22: =(C22-F22)/F22 -> 0.61923626 | O22: =(B22-F22)/F22 -> 0.81549843
A23: ASSETS | I23: ASSETS
A24: NON-CURRENT ASSETS | I24: NON-CURRENT ASSETS
A25: Tangible Assets | B25: 3509.64 | C25: 3706.42 | D25: 3954.46 | E25: 4178.9 | F25: 4507.17 | I25: Tangible Assets | L25: =(E25-F25)/F25 -> -0.072832842 | M25: =(D25-F25)/F25 -> -0.12262906 | N25: =(C25-F25)/F25 -> -0.17766137 | O25: =(B25-F25)/F25 -> -0.2213207
A26: Intangible Assets | B26: 1.71 | C26: 2.21 | D26: 2.2 | E26: 1.22 | F26: 0.76 | I26: Intangible Assets | L26: =(E26-F26)/F26 -> 0.60526316 | M26: =(D26-F26)/F26 -> 1.8947368 | N26: =(C26-F26)/F26 -> 1.9078947 | O26: =(B26-F26)/F26 -> 1.25
A27: Capital Work-In-Progress | B27: 17.56 | C27: 15.53 | D27: 23.44 | E27: 33.85 | F27: 108.85 | I27: Capital Work-In-Progress | L27: =(E27-F27)/F27 -> -0.68902159 | M27: =(D27-F27)/F27 -> -0.78465779 | N27: =(C27-F27)/F27 -> -0.8573266 | O27: =(B27-F27)/F27 -> -0.83867708
A28: Other Assets | B28: 0 | C28: 0 | D28: 0 | E28: 0 | F28: 0 | I28: Other Assets
A29: Fixed Assets | B29: 3531.7 | C29: 3724.16 | D29: 3980.1 | E29: 4213.97 | F29: 4616.78 | I29: Fixed Assets | L29: =(E29-F29)/F29 -> -0.087249122 | M29: =(D29-F29)/F29 -> -0.13790564 | N29: =(C29-F29)/F29 -> -0.19334255 | O29: =(B29-F29)/F29 -> -0.23502961
A30: Non-Current Investments | B30: 17335.47 | C30: 14654.68 | D30: 6654.04 | E30: 7674.34 | F30: 5082.7 | I30: Non-Current Investments | L30: =(E30-F30)/F30 -> 0.50989435 | M30: =(D30-F30)/F30 -> 0.30915458 | N30: =(C30-F30)/F30 -> 1.8832471 | O30: =(B30-F30)/F30 -> 2.4106813
A31: Deferred Tax Assets [Net] | B31: 0 | C31: 0 | D31: 0 | E31: 0 | F31: 0 | I31: Deferred Tax Assets [Net]
A32: Long Term Loans And Advances | B32: 80.97 | C32: 79.85 | D32: 73.62 | E32: 102.53 | F32: 205.13 | I32: Long Term Loans And Advances | L32: =(E32-F32)/F32 -> -0.50017062 | M32: =(D32-F32)/F32 -> -0.64110564 | N32: =(C32-F32)/F32 -> -0.61073466 | O32: =(B32-F32)/F32 -> -0.6052747
A33: Other Non-Current Assets | B33: 1401.72 | C33: 1255.27 | D33: 1213.37 | E33: 1179.08 | F33: 1160.44 | I33: Other Non-Current Assets | L33: =(E33-F33)/F33 -> 0.016062873 | M33: =(D33-F33)/F33 -> 0.045612009 | N33: =(C33-F33)/F33 -> 0.081719003 | O33: =(B33-F33)/F33 -> 0.20792113
A34: Total Non-Current Assets | B34: 22349.86 | C34: 19713.96 | D34: 11921.13 | E34: 13169.92 | F34: 11065.05 | I34: Total Non-Current Assets | L34: =(E34-F34)/F34 -> 0.19022689 | M34: =(D34-F34)/F34 -> 0.077367929 | N34: =(C34-F34)/F34 -> 0.7816422 | O34: =(B34-F34)/F34 -> 1.0198607
A35: CURRENT ASSETS | I35: CURRENT ASSETS
A36: Current Investments | B36: 77.97 | C36: 75.82 | D36: 212.6 | E36: 537.56 | F36: 334.1 | I36: Current Investments | L36: =(E36-F36)/F36 -> 0.60897935 | M36: =(D36-F36)/F36 -> -0.36366357 | N36: =(C36-F36)/F36 -> -0.77306196 | O36: =(B36-F36)/F36 -> -0.76662676
A37: Inventories | B37: 439.13 | C37: 781.86 | D37: 776.09 | E37: 236.34 | F37: 540.77 | I37: Inventories | L37: =(E37-F37)/F37 -> -0.56295652 | M37: =(D37-F37)/F37 -> 0.43515728 | N37: =(C37-F37)/F37 -> 0.44582725 | O37: =(B37-F37)/F37 -> -0.18795421
A38: Trade Receivables | B38: 623.75 | C38: 644.73 | D38: 300.51 | E38: 253 | F38: 797.12 | I38: Trade Receivables | L38: =(E38-F38)/F38 -> -0.68260739 | M38: =(D38-F38)/F38 -> -0.62300532 | N38: =(C38-F38)/F38 -> -0.19117573 | O38: =(B38-F38)/F38 -> -0.21749548
A39: Cash And Cash Equivalents | B39: 830.52 | C39: 435.08 | D39: 203.01 | E39: 127.33 | F39: 157.6 | I39: Cash And Cash Equivalents | L39: =(E39-F39)/F39 -> -0.19206853 | M39: =(D39-F39)/F39 -> 0.28813452 | N39: =(C39-F39)/F39 -> 1.7606599 | O39: =(B39-F39)/F39 -> 4.269797
A40: Short Term Loans And Advances | B40: 153.98 | C40: 118.41 | D40: 869.99 | E40: 65.84 | F40: 250.83 | I40: Short Term Loans And Advances | L40: =(E40-F40)/F40 -> -0.73751146 | M40: =(D40-F40)/F40 -> 2.4684448 | N40: =(C40-F40)/F40 -> -0.52792728 | O40: =(B40-F40)/F40 -> -0.38611809
...

Sheet Variance Analysis P&L
A1: Column1 | B1: Column2 | C1: Column3
A2: JSW Energy | B2: Previous Years �
A3: Income Statement | B3: ------------------- in Rs. Cr. -------------------
B4: Mar 24 | C4: 44986
B5: 12 mths | C5: 12 mths | G5: Variance from PY | H5: % change | K5: Average Variance | L5: =AVERAGE(G6:G41) -> -125.98615
A6: INCOME | G6: =+B7-C7 -> -618.78 | H6: =+G6/C7 -> -0.1080097 | K6: Average % change | L6: =AVERAGE(H6:H41) -> 0.008926592
A7: Revenue From Operations [Gross] | B7: 5110.15 | C7: 5728.93 | G7: =+B8-C8 -> -618.78 | H7: =+G7/C8 -> -0.1080097
A8: Revenue From Operations [Net] | B8: 5110.15 | C8: 5728.93 | G8: =+B9-C9 -> 8.64 | H8: =+G8/C9 -> 0.83883495
A9: Other Operating Revenues | B9: 18.94 | C9: 10.3 | G9: =+B10-C10 -> -610.14 | H9: =+G9/C10 -> -0.10631043
A10: Total Operating Revenues | B10: 5129.09 | C10: 5739.23 | G10: =+B11-C11 -> -69.45 | H10: =+G10/C11 -> -0.24816866
A11: Other Income | B11: 210.4 | C11: 279.85 | G11: =+B12-C12 -> -679.59 | H11: =+G11/C12 -> -0.11290596
A12: Total Revenue | B12: 5339.49 | C12: 6019.08
A13: EXPENSES | G13: =+B14-C14 -> -237.29 | H13: =+G13/C14 -> -0.66945973
A14: Purchase Of Stock-In Trade | B14: 117.16 | C14: 354.45 | G14: =+B15-C15 -> -912.81 | H14: =+G14/C15 -> -0.25052214
A15: Cost Of Fuel | B15: 2730.82 | C15: 3643.63 | G15: =+B16-C16 -> 18.5 | H15: =+G15/C16 -> 0.13731166
A16: Employee Benefit Expenses | B16: 153.23 | C16: 134.73 | G16: =+B17-C17 -> 218.07 | H16: =+G16/C17 -> 0.83937644
A17: Finance Costs | B17: 477.87 | C17: 259.8 | G17: =+B18-C18 -> -47.88 | H17: =+G17/C18 -> -0.15084116
A18: Depreciation And Amortisation Expenses | B18: 269.54 | C18: 317.42 | G18: =+B19-C19 -> 10.12 | H18: =+G18/C19 -> 0.02533547
A19: Other Expenses | B19: 409.56 | C19: 399.44 | G19: =+B20-C20 -> -951.29 | H19: =+G19/C20 -> -0.18618174
A20: Total Expenses | B20: 4158.18 | C20: 5109.47
B21: 45352 | C21: 44986
B22: 12 mths | C22: 12 mths | G22: =+B23-C23 -> 271.7 | H22: =+G22/C23 -> 0.29869944
A23: Profit/Loss Before Exceptional, ExtraOrdinary Items And Tax | B23: 1181.31 | C23: 909.61 | G23: =+B24-C24 -> -120 | H23: =+G23/C24 -> -1
A24: Exceptional Items | B24: 0 | C24: 120 | G24: =+B25-C25 -> 151.7 | H24: =+G24/C25 -> 0.14733734
A25: Profit/Loss Before Tax | B25: 1181.31 | C25: 1029.61
A26: Tax Expenses-Continued Operations | G26: =+B27-C27 -> 53.29 | H26: =+G26/C27 -> 0.34007658
A27: Current Tax | B27: 209.99 | C27: 156.7 | G27: =+B28-C28 -> -140.79 | H27: =+G27/C28 -> -0.86966459
A28: Deferred Tax | B28: 21.1 | C28: 161.89 | G28: =+B29-C29 -> -87.5 | H28: =+G28/C29 -> -0.27464767
A29: Total Tax Expenses | B29: 231.09 | C29: 318.59 | G29: =+B30-C30 -> 239.2 | H29: =+G29/C30 -> 0.3364181
A30: Profit/Loss After Tax And Before ExtraOrdinary Items | B30: 950.22 | C30: 711.02 | G30: =+B31-C31 -> 239.2 | H30: =+G30/C31 -> 0.3364181
A31: Profit/Loss From Continuing Operations | B31: 950.22 | C31: 711.02 | G31: =+B32-C32 -> 239.2 | H31: =+G31/C32 -> 0.3364181
A32: Profit/Loss For The Period | B32: 950.22 | C32: 711.02 | G32: =+B33-C33 -> 366 | H32: =+G32/C33 -> 0.0081358645
B33: 45352 | C33: 44986
B34: 12 mths | C34: 12 mths
A35: OTHER ADDITIONAL INFORMATION
A36: EARNINGS PER SHARE | G36: =+B37-C37 -> 1.46 | H36: =+G36/C37 -> 0.33718245
A37: Basic EPS (Rs.) | B37: 5.79 | C37: 4.33 | G37: =+B38-C38 -> 1.45 | H37: =+G37/C38 -> 0.33487298
A38: Diluted EPS (Rs.) | B38: 5.78 | C38: 4.33
A39: VALUE OF IMPORTED AND INDIGENIOUS RAW MATERIALS
A40: STORES, SPARES AND LOOSE TOOLS
...

Sheet Vertical Analysis P&L
A1: Column1 | B1: Column2 | C1: Column3 | D1: Column4 | E1: Column5 | F1: Column6 | H1: Vertical Analysis of Income Statement
A2: JSW Energy | B2: Previous Years �
A3: Income Statement | B3: ------------------- in Rs. Cr. -------------------
B4: Mar 24 | C4: 44986 | D4: 44621 | E4: 44256 | F4: 43891 | P4: V% Points
B5: 12 mths | C5: 12 mths | D5: 12 mths | E5: 12 mths | F5: 12 mths | H5: =A6 -> INCOME | I5: 2020 | J5: 2021 | K5: 2022 | L5: 2023 | M5: 2024 | P5: 2024 vs 2023
A6: INCOME | H6: =A7 -> Revenue From Operations [Gross] | I6: =F7/F$12 -> 0.95259415 | J6: =E7/E$12 -> 0.97425286 | K6: =D7/D$12 -> 0.93885043 | L6: =C7/C$12 -> 0.95179496 | M6: =B7/B$12 -> 0.95704833 | P6: =M6-L6 -> 0.0052533736
A7: Revenue From Operations [Gross] | B7: 5110.15 | C7: 5728.93 | D7: 3634.29 | E7: 2883.73 | F7: 4298 | H7: =A8 -> Revenue From Operations [Net] | I7: =F8/F$12 -> 0.95259415 | J7: =E8/E$12 -> 0.97425286 | K7: =D8/D$12 -> 0.93885043 | L7: =C8/C$12 -> 0.95179496 | M7: =B8/B$12 -> 0.95704833 | P7: =M7-L7 -> 0.0052533736
A8: Revenue From Operations [Net] | B8: 5110.15 | C8: 5728.93 | D8: 3634.29 | E8: 2883.73 | F8: 4298 | H8: =A9 -> Other Operating Revenues | I8: =F9/F$12 -> 0.0035439694 | J8: =E9/E$12 -> 0.0046622567 | K8: =D9/D$12 -> 0.0021828985 | L8: =C9/C$12 -> 0.001711225 | M8: =B9/B$12 -> 0.0035471553 | P8: =M8-L8 -> 0.0018359303
A9: Other Operating Revenues | B9: 18.94 | C9: 10.3 | D9: 8.45 | E9: 13.8 | F9: 15.99 | H9: =A10 -> Total Operating Revenues | I9: =F10/F$12 -> 0.95613812 | J9: =E10/E$12 -> 0.97891511 | K9: =D10/D$12 -> 0.94103332 | L9: =C10/C$12 -> 0.95350618 | M9: =B10/B$12 -> 0.96059549 | P9: =M9-L9 -> 0.0070893039
A10: Total Operating Revenues | B10: 5129.09 | C10: 5739.23 | D10: 3642.74 | E10: 2897.53 | F10: 4313.99 | H10: =A11 -> Other Income | I10: =F11/F$12 -> 0.043861885 | J10: =E11/E$12 -> 0.021084887 | K10: =D11/D$12 -> 0.058966675 | L10: =C11/C$12 -> 0.046493816 | M10: =B11/B$12 -> 0.039404512 | P10: =M10-L10 -> -0.0070893039
